Workbook

Sheet in
A1: index | B1: Job Title | C1: Salary Estimate | D1: Job Description | E1: Rating | F1: Company Name | G1: Location | H1: Headquarters | I1: Size | J1: Founded | K1: Type of ownership | L1: Industry | M1: Sector | N1: Revenue | O1: Competitors
A2: 0 | B2: Sr Data Scientist | C2: $137K-$171K (Glassdoor est.) | D2: Description The Senior Data Scientist is responsible for defining, building, and improving statistical models to improve business processes and outcomes in one or more healthcare domains such as Clinical, Enrollment, Claims, and Finance. As part of the broader analytics team, Data Scientist will gather and analyze data to solve and address complex business problems and evaluate scenarios to make predictions on future outcomes and work with the business to communicate and support decision-making. This position requires strong analytical skills and experience in analytic methods including multivariate regressions, hierarchical linear models, regression trees, clustering methods and other complex statistical techniques. Duties & Responsibilities: â€¢ Develops advanced statistical models to predict, quantify or forecast various operational and performance metrics in multiple healthcare domains â€¢ Investigates, recommends, and initiates acquisition of new data resources from internal and external sources â€¢ Works with multiple teams to support data collection, integration, and retention requirements based on business needs â€¢ Identifies critical and emerging technologies that will support and extend quantitative analytic capabilities â€¢ Collaborates with business subject matter experts to select relevant sources of information â€¢ Develops expertise with multiple machine learning algorithms and data science techniques, such as exploratory data analysis and predictive modeling, graph theory, recommender systems, text analytics and validation â€¢ Develops expertise with Healthfirst datasets, data repositories, and data movement processes â€¢ Assists on projects/requests and may lead specific tasks within the project scope â€¢ Prepares and manipulates data for use in development of statistical models â€¢ Other duties as assigned Minimum Qualifications: -Bachelor's Degree Preferred Qualifications: - Masterâ€™s degree in Computer Science or Statistics Familiarity with major cloud platforms such as AWS and Azure Healthcare Industry Experience Minimum Qualifications: -Bachelor's Degree Preferred Qualifications: - Masterâ€™s degree in Computer Science or Statistics Familiarity with major cloud platforms such as AWS and Azure Healthcare Industry Experience WE ARE AN EQUAL OPPORTUNITY EMPLOYER. Applicants and employees are considered for positions and are evaluated without regard to mental or physical disability, race, color, religion, gender, national origin, age, genetic information, military or veteran status, sexual orientation, marital status or any other protected Federal, State/Province or Local status unrelated to the performance of the work involved. If you have a disability under the Americans with Disability Act or a similar law, and want a reasonable accommodation to assist with your job search or application for employment, please contact us by sending an email to careers@Healthfirst.org or calling 212-519-1798 . In your email please include a description of the accommodation you are requesting and a description of the position for which you are applying. Only reasonable accommodation requests related to applying for a position within Healthfirst Management Services will be reviewed at the e-mail address and phone number supplied. Thank you for considering a career with Healthfirst Management Services. EEO Law Poster and Supplement ]]> | E2: 3.1 | F2: Healthfirst 3.1 | G2: New York, NY | H2: New York, NY | I2: 1001 to 5000 employees | J2: 1993 | K2: Nonprofit Organization | L2: Insurance Carriers | M2: Insurance | N2: Unknown / Non-Applicable | O2: EmblemHealth, UnitedHealth Group, Aetna
A3: 1 | B3: Data Scientist | C3: $137K-$171K (Glassdoor est.) | D3: Secure our Nation, Ignite your Future Join the top Information Technology and Analytic professionals in the industry to make invaluable contributions to our national security on a daily basis. In this innovative, self-contained, Big Data environment, the ManTech team is responsible for everything from infrastructure, to application development, to data science, to advanced analytics and beyond. The team is diverse, the questions are thought-provoking, and the opportunities for growth and advancement are numerous The successful candidate will possess a diverse range of data-focused skills and experience, both technical and analytical. They will have a strong desire and capability for problem solving, data analysis and troubleshooting, analytical thinking, and experimentation. Duties, Tasks & Responsibilities Working with large, complex, and disparate data sets Designing and implementing innovative ways to analyze and exploit the Sponsors data holdings Researching and reporting on a wide variety of Sponsor inquiries Raising proactive inquiries to the Sponsor based on observations and proposed data analysis/exploitation Solving difficult, non-routine problems by applying advanced analytical methodologies, and improving analytic methodologies Developing custom searches Communicating and coordinating with internal and external partners as needed Required Experience, Skills, & Technologies Thorough knowledge of appropriate analytic tools and methodologies in one or more of the following: Applied mathematics (e.g. probability and statistics, formal modeling, computational social sciences) Computer programming (e.g. programming languages, math/statistics packages, computer science, machine learning, scientific computing) Ability to code or script in one or more general programming language Experience with and theoretical understanding of algorithms for classification, regression, clustering, and anomaly detection Knowledge of relational databases, including SQL and large-scale distributed systems (e.g. Hadoop) Expertise with statistical data analysis (e.g. linear models, multivariate analysis, stochastic models, sampling methods) Demonstrated effectiveness in collecting information and accurately representing/visualizing it to non-technical third parties TS/SCI with Polygraph Bachelor of Science or equivalent and 12-15 years related experience, but will consider all levels of experience. Desired Experience, Skills & Technologies Previous investigative experience using a combination of technical and analytic skills #LI-DU1 ManTech International Corporation, as well as its subsidiaries proactively fulfills its role as an equal opportunity employer. We do not discriminate against any employee or applicant for employment because of race, color, sex, religion, age, sexual orientation, gender identity and expression, national origin, marital status, physical or mental disability, status as a Disabled Veteran, Recently Separated Veteran, Active Duty Wartime or Campaign Badge Veteran, Armed Forces Services Medal, or any other characteristic protected by law. If you require a reasonable accommodation to apply for a position with ManTech through its online applicant system, please contact ManTech's Corporate EEO Department at (703) 218-6000. ManTech is an affirmative action/equal opportunity employer - minorities, females, disabled and protected veterans are urged to apply. ManTech's utilization of any external recruitment or job placement agency is predicated upon its full compliance with our equal opportunity/affirmative action policies. ManTech does not accept resumes from unsolicited recruiting firms. We pay no fees for unsolicited services. If you are a qualified individual with a disability or a disabled veteran, you have the right to request an accommodation if you are unable or limited in your ability to use or access http://www.mantech.com/careers/Pages/careers.aspx as a result of your disability. To request an accommodation please click careers@mantech.com and provide your name and contact information. | E3: 4.2 | F3: ManTech 4.2 | G3: Chantilly, VA | H3: Herndon, VA | I3: 5001 to 10000 employees | J3: 1968 | K3: Company - Public | L3: Research & Development | M3: Business Services | N3: $1 to $2 billion (USD) | O3: -1
A4: 2 | B4: Data Scientist | C4: $137K-$171K (Glassdoor est.) | D4: Overview Analysis Group is one of the largest international economics consulting firms, with more than 1,000 professionals across 14 offices in North America, Europe, and Asia. Since 1981, we have provided expertise in economics, finance, health care analytics, and strategy to top law firms, Fortune Global 500 companies, and government agencies worldwide. Our internal experts, together with our network of affiliated experts from academia, industry, and government, offer our clients exceptional breadth and depth of expertise. We are currently seeking a Data Scientist to join our team. The ideal candidate should be passionate about working on cutting edge research and analytical services for Fortune 500 companies, global pharma/biotech firms and leaders in industries such as finance, energy and life sciences. The Data Scientist will be a contributing member to client engagements and have the opportunity to work with our network of world-class experts and thought leaders. Job Functions and Responsibilities The candidate Data Scientist will help develop, maintain and teach new tools and methodologies related to data science and high performance computing. This position will also help Analysis Group in maintaining our leadership position in terms of advancing methodology and data analytics. The Data Scientist will be responsible for staying abreast of new developments in technology relating to data science, to share more broadly with Analysis Group. Key responsibilities for this position will include: Working with project teams to address data science/computing challenges Identifying opportunities for technology to enhance service offerings Acting as a resource and participating in client engagements and research as part of the project team Maintaining up-to-date knowledge of computing tools, providing technical training and helping to grow the in-house knowledge base, specifically in a Linux environment Presenting research at selected conferences Examples of activities for the Data Scientist will include: Developing data engineering and machine learning production systems for full stack data science projects Using natural language processing methodologies to work with EMR data, social media data and other unstructured data Optimizing procedures for managing and accessing large databases (e.g., insurance claims, electronic health records, financial transactions) Creating interactive analytics portals and data visualizations (e.g., using R/Shiny, Python/Flask, D3) Building and maintaining high performance computing (HPC) tools on grid and cloud computing environments Developing and reviewing software and packages in R, Python and other Object Oriented Languages Establishing optimized procedures for repetitive or computationally intensive tasks (C, C++, Cuda-C) Qualifications Strong credentials and experience in database management and data visualization Significant experience working within a Linux environment required Background in Statistics/Econometrics or Biostatistics Ideally PhD in Computer Science, Mathematics, Statistics, Economics or other relevant scientific degree with relevant experience. Other candidates with at least one year of experience in the field may also be considered Excellent written and verbal communication skills Project experience with R and/or Python Familiar with online/cloud computing/storage (e.g., AWS) Demonstrated experience working on project teams and collaborating with others SCIENTIFIQUE DES DONNÃ‰ES *Lâ€™utilisation du genre masculin sert uniquement Ã allÃ©ger le texte et est utilisÃ© ici en tant que genre neutre Survol Groupe dâ€™analyse ltÃ©e est lâ€™une des plus grandes firmes de services-conseils en Ã©conomie, comptant plus de 950 professionnels rÃ©partis dans 14 bureaux en AmÃ©rique du Nord, en Europe et en Asie. Depuis 1981, nous offrons notre expertise en matiÃ¨re de stratÃ©gie, dâ€™Ã©conomie, de finance et dâ€™analyse dans le domaine des soins de santÃ© aux grands cabinets dâ€™avocats, aux sociÃ©tÃ©s Fortune Global 500 et aux agences gouvernementales du monde entier. Nos professionnels en poste conjuguÃ©s Ã notre rÃ©seau de spÃ©cialistes affiliÃ©s issus dâ€™universitÃ©s, dâ€™industries spÃ©cifiques et dâ€™organismes gouvernementaux procurent Ã notre clientÃ¨le un savoir-faire dâ€™une portÃ©e et dâ€™une profondeur exceptionnelles. Nous sommes prÃ©sentement Ã la recherche d'un Scientifique des donnÃ©es (Â« Data Scientist Â») pour se joindre Ã notre Ã©quipe. Le candidat idÃ©al devrait Ãªtre passionnÃ© par la recherche de pointe et les services analytiques pour les entreprises Fortune 500, les entreprises pharmaceutiques et biotechnologiques mondiales et les chefs de file dans des secteurs de la finance, l'Ã©nergie et les sciences de la vie. Le Scientifique des donnÃ©es sera un membre contributeur aux mandats des clients et aura l'occasion de travailler avec notre rÃ©seau d'experts et de leaders d'opinion de classe mondiale. Description du poste et des responsabilitÃ©s Le scientifique des donnÃ©es aidera Ã dÃ©velopper, maintenir et enseigner de nouveaux outils et mÃ©thodologies liÃ©s Ã la science des donnÃ©es (Â« Data Science Â») et au HPC. Ce poste aidera Ã©galement le Groupe d'analyse Ã maintenir sa position de chef de file en ce qui a trait Ã l'avancement de la mÃ©thodologie et de l'analyse des donnÃ©es. Le scientifique des donnÃ©es sera chargÃ© de se tenir au courant des nouveaux dÃ©veloppements technologiques liÃ©s Ã la science des donnÃ©es, afin de les partager plus largement avec le Groupe d'analyse. Les principales responsabilitÃ©s de ce poste comprendront: - Collaborer avec les consultants pour relever les dÃ©fis de la science des donnÃ©es et de sciences informatiques - Agir Ã titre de ressource et participer aux mandats et Ã la recherche en tant que membre de l'Ã©quipe de projet - Maintenir Ã jour les connaissances sur les outils informatiques, fournir une formation technique et aider Ã dÃ©velopper la base de connaissances interne, notamment dans un environnement Linux - PrÃ©senter la recherche Ã des confÃ©rences choisies Exemples de tÃ¢ches du scientifique des donnÃ©es : - DÃ©veloppement de systÃ¨mes de production en ingÃ©nierie des donnÃ©es ainsi quâ€™en apprentissage machine pour des projets de science des donnÃ©es full stack - Utiliser des mÃ©thodologies NLP pour travailler avec les donnÃ©es mÃ©dicales Ã©lectroniques, les donnÃ©es des mÃ©dias sociaux et d'autres donnÃ©es non structures - Optimiser les procÃ©dures de gestion et d'accÃ¨s aux grandes bases de donnÃ©es (ex. rÃ©clamations d'assurance, dossiers de santÃ© Ã©lectroniques, transactions financiÃ¨res) - CrÃ©ation de portails d'analyse interactifs et de visualisations de donnÃ©es (par exemple, en utilisant R/Shiny, Python/Flask, D3) - Construire et maintenir des outils de calcul de haute performance (HPC). - DÃ©veloppement et rÃ©vision de codes en R, Python et autres langages - Mise en place de procÃ©dures optimisÃ©es pour les tÃ¢ches rÃ©pÃ©titives ou intensives en calcul (C, C++, Cuda-C) Qualifications requises - Solides rÃ©fÃ©rences et expÃ©rience dans la gestion de bases de donnÃ©es et de la visualisation de donnÃ©es - ExpÃ©rience de travail significative dans un environnement Linux requise - ExpÃ©rience antÃ©rieure en statistique/Ã©conomÃ©trie ou bio-statistique - IdÃ©alement, Ãªtre titulaire d'un doctorat en sciences informatiques, en mathÃ©matiques, en statistique, en Ã©conomie ou d'un autre diplÃ´me scientifique pertinent et possÃ©der une expÃ©rience pertinente. Les candidats ayant au moins un an d'expÃ©rience dans le domaine peuvent Ã©galement Ãªtre considÃ©rÃ©s. - Excellentes aptitudes de communication Ã©crite et verbale - ExpÃ©rience de projet avec R et/ou Python - FamiliaritÃ© avec l'informatique en ligne/info nuagique et le stockage (AWS) - ExpÃ©rience de travail dÃ©montrÃ©e au sein d'Ã©quipes de projet et de collaboration avec d'autres personnes Â­ Equal Opportunity Employer/Protected Veterans/Individuals with Disabilities. Please view Equal Employment Opportunity Posters provided by OFCCP here. The contractor will not discharge or in any other manner discriminate against employees or applicants because they have inquired about, discussed, or disclosed their own pay or the pay of another employee or applicant. However, employees who have access to the compensation information of other employees or applicants as a part of their essential job functions cannot disclose the pay of other employees or applicants to individuals who do not otherwise have access to compensation information, unless the disclosure is (a) in response to a formal complaint or charge, (b) in furtherance of an investigation, proceeding, hearing, or action, including an investigation conducted by the employer, or (c) consistent with the contractor's legal duty to furnish information. 41 CFR 60-1.35(c) | E4: 3.8 | F4: Analysis Group 3.8 | G4: Boston, MA | H4: Boston, MA | I4: 1001 to 5000 employees | J4: 1981 | K4: Private Practice / Firm | L4: Consulting | M4: Business Services | N4: $100 to $500 million (USD) | O4: -1
A5: 3 | B5: Data Scientist | C5: $137K-$171K (Glassdoor est.) | D5: JOB DESCRIPTION: Do you have a passion for Data and Machine Learning? Do you dream of working with customers on their most forward-looking AI initiatives? Does the challenge of developing modern machine learning solutions to solve real-world manufacturing problems exciting to you? We develop software for monitoring semiconductor manufacturing process and are looking to leverage the latest technologies to address our customer's needs. You will be part of a team that investigates and builds solutions based all the data available in factories, ranging from time series data, to post manufacturing data, to production logs. You will be working side by side with application developers and customers on real world problems with actual manufacturing data. JOB FUNCTION: Basic and applied research in statistical machine learning, deep learning, and data science as well as signal and information processing to advance the state of the art in time series analysis of semiconductor manufacturing data. Responsibilities: Perform data analysis, data pre-processing, and feature engineering in support of advanced machine learning algorithm development. Incorporate physical and operational insights/constraints into statistical models to achieve a high degree of robustness. Prototype algorithms for proof of concept, validation, and software implementation. Support performance evaluations and the transition of algorithms into existing fault detection and classification systems. Convey the results of scientific research to sponsors and the scientific community through briefings, conferences and peer-reviewed publications. Other related functions as assigned. REQUIRED QUALIFICATIONS: Bachelor's degree in computer science or chemical engineering or related technical field. Demonstrated ability in machine learning/artificial intelligence (ML/AI) development and/or scientific modelling and data analysis. Demonstrated ability with python/MATLAB or similar abstract language. Experience with both traditional ML and modern deep learning approaches. Experience with agile development practices and Git version control. Experience with one or more of the DNN frameworks like TensorFlow, PyTorch, Chainer. Experience with SQL, Graph stores, or NoSQL stores. Applicant must have a dynamic skill set, be willing to work with new technologies, be highly organized and capable of planning and coordinating multiple tasks. The position will require attention to detail, effective problem solving skills and excellent judgment. Ability to work independently with sensitive and confidential information, maintain a professional demeanor, work as a team member without daily supervision. COMPENSATION & BENEFITS: Compensation will be commensurate with experience including a competitive base salary, bonus opportunity, competitive benefits package, and relocation assistance. INFICON, is committed to ensuring that our online application process provides an equal opportunity to all job seekers that apply without regard to race, religion, ethnicity, national origin, citizenship, gender, age, protected veteran status, disability status, genetic information, sexual orientation, or any other protected characteristic. A notice describing Federal equal employment opportunity laws is available here and here to reaffirm this commitment. PI120660357 | E5: 3.5 | F5: INFICON 3.5 | G5: Newton, MA | H5: Bad Ragaz, Switzerland | I5: 501 to 1000 employees | J5: 2000 | K5: Company - Public | L5: Electrical & Electronic Manufacturing | M5: Manufacturing | N5: $100 to $500 million (USD) | O5: MKS Instruments, Pfeiffer Vacuum, Agilent Technologies
A6: 4 | B6: Data Scientist | C6: $137K-$171K (Glassdoor est.) | D6: Data Scientist Affinity Solutions / Marketing Cloud seeks smart, curious, technically savvy candidates to join our cutting-edge data science team. We hire the best and brightest and give them the opportunity to work on industry-leading technologies. The data sciences team at AFS/Marketing Cloud build models, machine learning algorithms that power all our ad-tech/mar-tech products at scale, develop methodology and tools to precisely and effectively measure market campaign effects, and research in-house and public data sources for consumer spend behavior insights. In this role, you'll have the opportunity to come up with new ideas and solutions that will lead to improvement of our ability to target the right audience, derive insights and provide better measurement methodology for marketing campaigns. You'll access our core data asset and machine learning infrastructure to power your ideas. Duties and Responsibilities Â· Support all clients model building needs, including maintaining and improving current modeling/scoring methodology and processes, Â· Provide innovative solutions to customized modeling/scoring/targeting with appropriate ML/statistical tools, Â· Provide analytical/statistical support such as marketing test design, projection, campaign measurement, market insights to clients and stakeholders. Â· Mine large consumer datasets in the cloud environment to support ad hoc business and statistical analysis, Â· Develop and Improve automation capabilities to enable customized delivery of the analytical products to clients, Â· Communicate the methodologies and the results to the management, clients and none technical stakeholders. Basic Qualifications Â· Advanced degree in Statistics/Mathematics/Computer Science/Economics or other fields that requires advanced training in data analytics. Â· Being able to apply basic statistical/ML concepts and reasoning to address and solve business problems such as targeting, test design, KPI projection and performance measurement. Â· Entrepreneurial, highly self-motivated, collaborative, keen attention to detail, willingness and capable learn quickly, and ability to effectively prioritize and execute tasks in a high pressure environment. Â· Being flexible to accept different task assignments and able to work on a tight time schedule. Â· Excellent command of one or more programming languages; preferably Python, SAS or R Â· Familiar with one of the database technologies such as PostgreSQL, MySQL, can write basic SQL queries Â· Great communication skills (verbal, written and presentation) Preferred Qualifications Â· Experience or exposure to large consumer and/or demographic data sets. Â· Familiarity with data manipulation and cleaning routines and techniques. | E6: 2.9 | F6: Affinity Solutions 2.9 | G6: New York, NY | H6: New York, NY | I6: 51 to 200 employees | J6: 1998 | K6: Company - Private | L6: Advertising & Marketing | M6: Business Services | N6: Unknown / Non-Applicable | O6: Commerce Signals, Cardlytics, Yodlee
A7: 5 | B7: Data Scientist | C7: $137K-$171K (Glassdoor est.) | D7: About Us: Headquartered in beautiful Santa Barbara, HG Insights is the global leader in technology intelligence. HG Insights uses advanced data science methodologies to help the world's largest technology firms and the fastest growing companies accelerate their sales, marketing, and strategy efforts. We offer a casual yet professional environment. Get your sweat on at one of our fitness classes or go for a run along the beach which is two blocks away. You can find employees riding bikes to lunch in the funk zone or hanging out in one of our collaboration spaces. We are passionate about our jobs with a get-it-done attitude, yet we don't take ourselves too seriously. What You'll Do: We are looking for a data scientist with software development or data engineering background to join our research team which reports directly to the CTO. We are a rapidly growing company with small focused engineering teams that deliver innovative features to a fast growing market. We build big-data systems utilizing cutting edge technologies and solutions that allow for our engineers to continuously learn and develop while shipping amazing products. Qualities/ Experience: Self-learner, hacker, technology advocate who can work on anything Amazing engineering skills, you're on your way to being the one of the best engineers you know You can architect, design, code, test, and mentor others Experience working with interesting and successful projects Thrive in a fast growing environment Excellent written and spoken English communication An interest in Machine Learning and Natural Language Processing What You'll Be Responsible For: Build solutions for text classification, entity linking, and entity extraction and other related projects Scaling machine learning and NLP projects to run against large datasets in virtualized environments. You will collaborate with Product Development Teams to build the most effective solutions You will develop features in our databases, backend apps, front end UI, and Data as a Service (DAAS) product You will help architect and design large scale enterprise big-data systems You will work on ideas from different team members as well as your own Fix bugs rapidly Attend daily stand-up meetings, planning sessions, encourage others, and collaborate at a rapid pace What You'll Need: BS, MS, or Ph.D. in Computer Science or related technical discipline Experience Natural Language Processing, preferably in a commercial setting. Experience building Logistic Regression Models Proficient in Python and Jupyter as well as related data science libraries (such as Scikit-learn, NLTK, SpaCy, Tensorflow) Proficient in Java or Scala (3+ years experience recommended) Experience with MySQL, ElasticSearch, ESB, Hadoop, Spark, or other related data processing/database technologies Experience with Amazon Web Services (EC2, S3, RDS, EMR, ELB, etc.) Experience with web services using REST in Java Actual coding experience in large distributed environments with multiple endpoints and complex interactions Comfortable in an agile development environment Understanding and have real world experience using design patterns Comfortable programming on a Mac with Intellij and other tools HG Insights Company is an Equal Opportunity Employer Please note that HG Insights does not accept unsolicited resumes from recruiters or employment agencies. In the event of a recruiter or agency submitting a resume or candidate without a signed agreement being in place, we explicitly reserve the right to pursue and hire such candidates without any financial obligation to the recruiter or agency. Any unsolicited resumes, including those submitted directly to hiring managers, are deemed to be the property of HG Insights | E7: 4.2 | F7: HG Insights 4.2 | G7: Santa Barbara, CA | H7: Santa Barbara, CA | I7: 51 to 200 employees | J7: 2010 | K7: Company - Private | L7: Computer Hardware & Software | M7: Information Technology | N7: Unknown / Non-Applicable | O7: -1
A8: 6 | B8: Data Scientist / Machine Learning Expert | C8: $137K-$171K (Glassdoor est.) | D8: Posting Title Data Scientist / Machine Learning Expert 04-Feb-2020 Job ID 288341BR Job Description ONE Global Discovery Chemistry Community working across 7 disease areas at the Novartis Institutes for BioMedical Research (NIBR) is seeking a highly talented and motivated Data Scientist to join our Global Discovery Chemistry Department in Cambridge, MA. The successful candidate will join an energizing and collaborative research organization, working alongside colleagues who are committed to improving human health through the discovery of transformative medicines. We are seeking a unique data scientist with the skills, experience and passion to extract new knowledge and disruptive insights from the large and rich body of data collected by one of the worldâ€™s leading pharmaceutical companies. You will be a member of our global Computer-Aided Drug Discovery (CADD) group, an interdisciplinary team of expert molecular modelers, cheminformaticians, and data scientists. Teamed up with domain experts from biology, chemistry and translational medicine, this is a unique opportunity to develop and apply cutting-edge machine learning technologies to uncover insights to real-world drug discovery problems and innovate paths to new medicines. Your responsibilities include: â€¢Develop and implement methods for extracting patterns and correlations from both internal and external data sources using machine learning toolkits â€¢Develop workflows for conducting comparative analysis among Novartisâ€™ diverse data sources as well as generalizing approaches developed in-house or externally. â€¢Enable open-source solutions for internal use and implement cutting-edge published scientific methods. â€¢Develop customized machine learning solutions including data querying and knowledge extraction. â€¢Interact and be part of interdisciplinary project teams to drive effective decision-making by mining and developing predictive models â€¢Develop new skills in the area of cheminformatics and drug discovery and leverage those to accelerate development of new machine learning algorithms â€¢Keep ahead of scientific literature and interact with internal and external scientists to integrate novel data science technologies Minimum requirements Education: Advanced degree (M.Sc. or higher) in data science and machine learning, statistics, computer sciences, cheminformatics, mathematics, computational chemistry, computational biology, bioinformatics, or related field. Minimum experience & skills: â€¢In-depth experience with modern and classical machine learning methods â€¢Strong statistical foundation with broad knowledge of supervised and unsupervised techniques â€¢Programming experience (preferred Python, R, C++) preferably in Linux and high-performance computing environments â€¢Good listener - strong, concise, and consistent written and oral communication â€¢Talent for communicating stories through data visualizations â€¢Proven ability to collaborate with others â€¢A passion for tackling challenging problems and developing creative solutions â€¢A drive for self-development with a focus on scientific know-how Additional qualifications that will help in the role: â€¢Demonstrated impact using machine learning libraries, such as scikit-learn, PyTorch or similar in a cheminformatics context â€¢Hands on experience with data analysis software such as Spotfire, R-shiny or similar â€¢Working experience with open-source cheminformatics toolkits such as RDKit â€¢Working experience with source-code management systems such as Git/github/bitbucket â€¢Familiar with the foundational concepts in molecular biology, pharmacology or medicine. Working knowledge of medicinal chemistry and drug discovery is a plus Why consider Novartis? 750 million. Thatâ€™s how many lives our products touch. And while weâ€™re proud of that fact, in this world of digital and technological transformation, we must also ask ourselves this: how can we continue to improve and extend even more peopleâ€™s lives? We believe the answers are found when curious, courageous and collaborative people like you are brought together in an inspiring environment. Where youâ€™re given opportunities to explore the power of digital and data. Where youâ€™re empowered to risk failure by taking smart risks, and where youâ€™re surrounded by people who share your determination to tackle the worldâ€™s toughest medical challenges. We are Novartis. Join us and help us reimagine medicine. Job Type Full Time Country USA Work Location Cambridge, MA Functional Area Research & Development Division NIBR Business Unit Global Discovery Chemistry Employment Type Regular Company/Legal Entity NIBRI EEO Statement The Novartis Group of Companies are Equal Opportunity Employers and take pride in maintaining a diverse environment. We do not discriminate in recruitment, hiring, training, promotion or any other employment practices for reasons of race, color, religion, gender, national origin, age, sexual orientation, marital or veteran status, disability, or any other legally protected status. Shift Work No | E8: 3.9 | F8: Novartis 3.9 | G8: Cambridge, MA | H8: Basel, Switzerland | I8: 10000+ employees | J8: 1996 | K8: Company - Public | L8: Biotech & Pharmaceuticals | M8: Biotech & Pharmaceuticals | N8: $10+ billion (USD) | O8: -1
A9: 7 | B9: Data Scientist | C9: $137K-$171K (Glassdoor est.) | D9: Introduction Have you always wanted to run experiments on a global fleet of consumer robots? iRobot is looking for a data scientist to help manage a/b tests related to robot software, track performance KPIs, and share results with software teams. A strong candidate has experience in experimental design, hypothesis testing, and statistics, in addition to strong SQL and Python skills. What You Will Do: Guide software and product management teams in designing rigorous experiments to test the impact of new software versions. Dashboarding to monitor results live from the fleet. Test hypotheses about software performance using appropriate statistical methods. Develop metrics to track software performance. Uphold scientific best practices in experimental design and cohort selection. Contribute to a management system for cohort selection. To Be Successful You Will Have: At least 1 year of relevant job, internship, or co-op experience. M.S. in computer science, statistics, mathematics, physics, chemistry, biology, or social sciences is a plus. Very detail-oriented and eager to get your hands dirty in the data. Proficient in Python, SQL, and data visualization, with experience using pandas, numpy, sklearn, scipy, matplotlib, or plotly. Experienced in designing experiments, making and testing hypotheses, and identifying the appropriate metrics to answer a question. Savvy in statistical methods and able to select the right test for each situation. Can balance business considerations with the need for scientific rigor. Self-motivated and comfortable working in a fast-paced, delivery-focused environment. Skilled communicator who can make the complicated seem simple. Passionate about using data to drive decision-making! | E9: 3.5 | F9: iRobot 3.5 | G9: Bedford, MA | H9: Bedford, MA | I9: 1001 to 5000 employees | J9: 1990 | K9: Company - Public | L9: Consumer Electronics & Appliances Stores | M9: Retail | N9: $1 to $2 billion (USD) | O9: -1
A10: 8 | B10: Staff Data Scientist - Analytics | C10: $137K-$171K (Glassdoor est.) | D10: Intuit is seeking a Staff Data Scientist to cover Intuits Consumer Group (TurboTax, Mint, Turbo). We have an exciting opportunity to help shape how we use data to generate hypotheses, surface insights, and build models in order to personalize customer experiences and provide awesome outcomes for the business and our customers. This role will partner closely with data engineering, data analytics, data science, marketing managers, and product management. | E10: 4.4 | F10: Intuit - Data 4.4 | G10: San Diego, CA | H10: Mountain View, CA | I10: 5001 to 10000 employees | J10: 1983 | K10: Company - Public | L10: Computer Hardware & Software | M10: Information Technology | N10: $2 to $5 billion (USD) | O10: Square, PayPal, H&R Block
A11: 9 | B11: Data Scientist | C11: $137K-$171K (Glassdoor est.) | D11: Ready to write the best chapter of your career? XSELL Technologies is an artificial intelligence company focused on increasing sales. Our cloud-based machine learning engine uses predictive analytics and natural language processing to equip sales professionals with the best real-time responses, driving improved conversion rates and customer experiences. We pride ourselves on our high performing, collaborative culture. We are passionate about our product, our clients, and our industry leading results. XSELL is currently seeking a Data Scientist to serve as a key member of our Data Science team. This role will work within the SAFe Agile framework of continuous delivery, work with other Data Scientists, and be a critical resource for our growing Data Science staff. Job Description Designing, implementing and improving XSELLâ€™s proprietary softwares, real time messaging recommendation systems, HiPerCoBot and QABOt using various mathematical, Natural Language Processing (NLP) algorithms and machine learning models. Developing new systems using Python NLP (lemmatization, stemming, named entity recognition) and updating the existing systems by adding new features to enhance the customers experience. Interacting with stakeholders to identify the requirements and define new processes. Closely work with the team to define the architecture of the Microservice environment and deploy systems using RESTful APIâ€™s. Planning, development, and analysis of dialogue prediction/sentiment models, causal models of customer/agent behavior. Improving the accuracy of the in house XSELL Recommendation System software suite by evaluating and monitoring annotations manually labelled by Ontology team. Analyzing and researching the current market trends for possible AI opportunities/improvements. Qualifications MS/PhD in a quantitative discipline (e.g. Machine Learning, Data Science, Computer Science, Mathematics, Statistics, or a related field). 3+ years full time employment or postdoctoral experience building and validating predictive models on structured or unstructured data. Proficiency in Python with knowledge of basic libraries for data manipulation, machine learning, natural language processing and text mining. Experience creating and using advanced machine learning algorithms (regression, neural networks, etc.) Understanding of deep learning algorithms and experience with related libraries such as TensorFlow, PyTorch. Nice to Have Experience in SQL. Understanding of object oriented design. Ability to craft new concepts and stay current with academic research Experience with graph databases and graph designs. Experience in designing/developing production level machine learning architectures (using Flask or Redis) We provide competitive compensation, generous benefits, and a professional atmosphere. XSELL fosters an entrepreneurial, results driven work environment where you will have the opportunity to be part of a collaborative, inclusive team and be able to grow and develop your professional career. XSELL Technologies is an Equal Employment Opportunity Employer and all employment decisions shall be made without regard to age, race, creed, color, religion, sex, national origin, ancestry, disability status, veteran status, sexual orientation, gender identity or expression, genetic information, marital status, citizenship status or any other basis as protected by federal, state, or local law. Location: Chicago, IL Role: Full-Time / Salaried | E11: 3.6 | F11: XSELL Technologies 3.6 | G11: Chicago, IL | H11: Chicago, IL | I11: 51 to 200 employees | J11: 2014 | K11: Company - Private | L11: Enterprise Software & Network Solutions | M11: Information Technology | N11: Unknown / Non-Applicable | O11: -1
A12: 10 | B12: Data Scientist | C12: $137K-$171K (Glassdoor est.) | D12: Join our team dedicated to developing and executing innovative solutions in support of customer mission success. Job Description: Novetta is seeking a Data Scientist who wants to develop innovative solutions for customers and internal product teams. We look to rapidly prototype solutions and deploy the most promising of them. We identify and leverage the latest techniques (fast.ai is a team favorite) so that our customers can stay one step ahead. On every project you'll learn something new (and likely teach us something as well). If that sounds appealing to you - we'd love to chat. Responsibilities include: Develop solutions spanning multiple subject areas, from NLP to Image and Video. Maintain awareness of state-of-the-art machine learning and techniques, methods and platforms, including commercial and open source. Implement, configure and test machine learning and deep learning libraries and platforms (e.g. fast.ai, TensorFlow, Keras, XGBoost, LightGBM). Test solutions on AWS using services such as SageMaker, EC2, and Snowball Edge. Write blog posts and presentations that clearly communicate complex machine learning concepts to both technical and non-technical audiences. Contribute to visually-appealing, web-enabled prototype applications that illustrate relevant machine learning capabilities. Basic Qualifications: Experience with Python Experience with machine learning or statistics Ability to work both independently and collaboratively. High levels of curiosity, creativity, and problem-solving capabilities. Strong written and verbal communication skills. Comfortable navigating the command line. Desired Skills: Research experience in Machine Learning specific to Natural Language Processing, Computer Vision, or deep learning. Experience with managing data and creating algorithms using AWS. Experience with R, Java, or other programming languages. Security Clearance: Must be eligible to obtain and maintain a TS/SCI with Poly clearance Novetta, from complexity to clarity. Novetta delivers highly scalable advanced analytics and secure technology solutions to address challenges of national and global significance. Focused on mission success, Novetta pioneers disruptive technologies in machine learning, data analytics, full-spectrum cyber, cloud engineering, open source analytics, and multi-INT fusion for Defense, Intelligence Community, and Federal Law Enforcement customers. Novetta is headquartered in McLean, VA with over 1,000 employees across the U.S. Our culture is shaped by a commitment to our core values: Integrity â€¢ We hold ourselves accountable to the highest standards of integrity and ethics. Customer Success â€¢ We strive daily to exceed expectations and achieve customer mission success. Employee Focus â€¢ We invest in our employees' professional development and training, respecting individuality and fostering a culture of diversity and inclusion. Innovation â€¢ We know that discovering new and innovative ways to solve problems is critical to our success and makes us a great company. Excellence in Execution â€¢ We take pride in flawless execution as we build a company that is best in class. Earn a REFERRAL BONUS for the qualified people you know. For more details or to submit a referral, visit bit.ly/NovettaReferrals. Novetta is an equal opportunity/affirmative action employer. All qualified applicants will receive consideration for employment without regard to sex, gender identity, sexual orientation, race, color, religion, national origin, disability, protected veteran status, age, or any other characteristic protected by law. | E12: 4.5 | F12: Novetta 4.5 | G12: Herndon, VA | H12: Mc Lean, VA | I12: 501 to 1000 employees | J12: 2012 | K12: Company - Private | L12: Enterprise Software & Network Solutions | M12: Information Technology | N12: $100 to $500 million (USD) | O12: Leidos, CACI International, Booz Allen Hamilton
A13: 11 | B13: Data Scientist | C13: $137K-$171K (Glassdoor est.) | D13: About Us Interested in working for a human-centered technology company that prides itself on using modern tools and technologies? Want to be surrounded by intensely curious and innovative thinkers? Seeking to solve complex technical challenges by building products that work for people, meet and exceed the needs of businesses, and work elegantly and efficiently? Modeling ourselves after the 1904 World's Fair, which brought innovation to the region, 1904labs is seeking top technical talent in St. Louis to bring innovation and creativity to our clients. Our clients consist of Fortune 500 and Global 2000 companies headquartered here in St. Louis. We partner with them on complex projects that range from reimagining and refactoring their existing applications, to helping to envision and build new applications or data streams to operationalize their existing data. Working in a team-based labs model, using our own flavor of #HCDAgile, we strive to work at the cutting edge of technology's capabilities while solving problems for our clients and their users. The Role As a Data Scientist with 1904labs, you will be working with other data scientists, data engineers, and developers to provide analytical services to clients. You will leverage the clients' data assets to answer business questions using best practices and innovative approaches. This will mean employing various data science tools (Python, apache spark, TensorFlow) and techniques (dimensionality reduction, unsupervised learning, supervised learning) to create and test machine learning algorithms. Once tested and verified you will work with development teams to implement the algorithm as a scalable, hosted service. We're looking for an experienced and creative data scientist who can conceptualize a project from start to finish, identifying the appropriate data and methodologies to use. Our Data Scientists work with open-source machine learning packages and libraries, so this position involves building custom ML/AI utilities from open-source resources in languages such as Python (preferred) and R. In this role, you will own and share technical solutions with both technical and non-technical stakeholders across multiple teams both internally and with external clients. Responsibilities Perform data analysis to understand the right combinations of data to meet outlined objectives Translate client queries into actionable data pulls and help translate outputs into client strategies Build and evaluate predictive modeling & machine learning utilities to produce meaningful outcomes that enable data-led decisions Translate analysis results into actionable insights Present insights to both technical and non-technical audiences Partner with internal data scientists, developers, and tech teams to develop new methodologies and utilities Work with development teams to implement data science algorithms as scalable, hosted services Your Skills Requirements Background in math including linear algebra, statistics, probability, and numerical analysis. Machine Learning Analysis: Must be able to execute, evaluate, and apply various models such as logistic regression, random forests/decision tree, nearest neighbor, neural net, support vector machine, an ensemble of multiple models, etc Programming: Proficient coding in a language suited for machine learning systems such as Python or R (not reliant on GUI-based systems to execute analysis) for the purpose of cleaning, manipulating, visualizing, and analyzing data Desired Skills Experience with software engineering and developing deployable API services Must be adaptable and have the drive to learn new technologies and frameworks to support developing client solutions Using browser based interactive computational environments (like Jupyter Notebook) to perform analysis activities and test / evaluate data models and algorithms. Tools: Spark, Pandas, SciKit-Learn, TensorFlow, Keras, SQL Communication: Must be able to explain analysis process and translate results into actionable insights for both technical and non-technical audiences Teamwork: Must be accountable for individual responsibilities while working collaboratively with development and engineering teams to achieve project deliverables Comfort in an agile development environment (eg. writing stories, participating in workshops, sprint planning and retros) Perks Benefits Program (medical, dental, life insurance, 401(k), professional and personal development, PTO) Innovation Time - we allow 10% of your time to be devoted to innovation hours. This time can be used to foster individual ideas, personal projects, start up ideas, improve an open source tool or for career advancement and self-education. All during traditional working hours. Dress Code - we don't have one These roles are located in St. Louis, MO. While we would prefer local candidates your location is not the most important factor; please help us understand why you would like to call St. Louis home if you would be relocating. ]]> | E13: 4.7 | F13: 1904labs 4.7 | G13: Saint Louis, MO | H13: Saint Louis, MO | I13: 51 to 200 employees | J13: 2016 | K13: Company - Private | L13: IT Services | M13: Information Technology | N13: Unknown / Non-Applicable | O13: Slalom, Daugherty Business Solutions
A14: 12 | B14: Data Scientist - Statistics, Early Career | C14: $137K-$171K (Glassdoor est.) | D14: *Organization and Job ID** Job ID: 310918 Directorate: National Security Directorate Division: Computing & Analytics Group: Applied Statistics & Computational Modeling *Job Description** This position is for a Scientist in Data Science and Applied or Mathematical Statistics who will provide scientific and technical research within the National Security Directorate (NSD) supporting the data analytics capabilities of the Computational Analytics Division. The Scientist will develop and apply fundamental mathematical or statistical theory to advance analytic solutions in various scientific domains. The Scientist must be able to draw from a strong statistical background, in areas including experimental design, advanced statistical modeling (e.g. mixed linear models, nonparametric models, etc.), machine learning, and computer simulations, to recognize patterns, characterize uncertainty, and develop predictive models using structured and unstructured data. The Scientist will produce solutions driven by domain science and mathematical statistical science from complex and high-dimensional datasets and design, develop, and evaluate advanced algorithms that lead to optimal value extraction from data. In addition to technical research this position expects participation and career development in task management, proposal writing, business development, and publishing. Operating on the data-information-knowledge continuum, staff at PNNL employ diverse methods to confront significant problems of national interest from distilling distributed data into knowledge that supports decision processes to enabling resilient technologies that enhance computing at extreme scales. Our research portfolio spanning from basic to applied includes statistical modeling and experimental design, applied statistics, applied mathematics, machine learning, operations research, optimization, and other advanced statistical and mathematical domains. Computing researchers and practitioners work side by side to apply advanced theories, methods, algorithms, models, evaluation tools and testbeds, and computational-based solutions to address complex scientific challenges affecting energy, biological sciences, the environment, and national security. Core domain knowledge is beneficial, such as in the nuclear, biological, energy, materials, or chemical science spaces. *The hiring level will be determined based on the education, experience, and skill set of the successful candidate based on the following:** *Level II** : Leads specific tasks of the project to meet scope, schedule and budget. Expected to contribute professionally, building a professional reputation for technical expertise. Fully applying and interpreting standard theories, principles, methods, tools and technologies. Contributes technical content to proposals and develops business through excellent project performance. *Level III:** Manages small to moderate projects and/or major project tasks. Integrates intellectual and technical capabilities of work teams. Enhances technical/professional skills of junior staff through active mentoring and training. Generates ideas for new proposals and participates in business development activities *Minimum Qualifications** + BS/BA with 2 years of experience, MS/MA with 0 years of experience, or PhD with 0 years of experience *Preferred Qualifications** + BS/BA with 5 years of experience, MS/MA with 3 years of experience, or PhD with 1 year of experience, focused in statistics with experience involving increasing levels of scientific research, task management, and programmatic responsibility + Position requires ability to apply theories and develop technical approaches with minimal oversight + Position requires the ability to effectively team with scientists and engineers to develop creative solutions to complex problems *Equal Employment Opportunity** Battelle Memorial Institute (BMI) at Pacific Northwest National Laboratory (PNNL) is an Affirmative Action/Equal Opportunity Employer and supports diversity in the workplace. All employment decisions are made without regard to race, color, religion, sex, national origin, age, disability, veteran status, marital or family status, sexual orientation, gender identity, or genetic information. All BMI staff must be able to demonstrate the legal right to work in the United States. BMI is an E-Verify employer. Learn more at jobs.pnnl.gov. *_Please be aware that the Department of Energy (DOE) prohibits DOE employees and contractors from participation in certain foreign government talent recruitment programs. If you are offered a position at PNNL and are currently a participant in a foreign government talent recruitment program you will be required to disclose this information before your first day of employment._** *Other Information** Due to business needs and client space, US Citizenship is required: The Pacific Northwest National Laboratory is subject to the Department of Energy Unclassified Foreign Visits & Assignment Program site, information, technologies, and equipment access requirements. _Directorate:_ _National Security_ _Job Category:_ _Scientists/Scientific Support_ _Group:_ _Appld Stats & Comp Modeling_ _Opening Date:_ _2020-06-03_ _Closing Date:_ _2020-09-01_ | E14: 3.7 | F14: PNNL 3.7 | G14: Richland, WA | H14: Richland, WA | I14: 1001 to 5000 employees | J14: 1965 | K14: Government | L14: Energy | M14: Oil, Gas, Energy & Utilities | N14: $500 million to $1 billion (USD) | O14: Oak Ridge National Laboratory, National Renewable Energy Lab, Los Alamos National Laboratory
A15: 13 | B15: Data Modeler | C15: $137K-$171K (Glassdoor est.) | D15: POSITION PURPOSE: The Data Architect/Data Modeler will be part of the OWI Analytic team. Our team works closely with our business partners, proactively developing and delivering analytic solutions.The Primary Deliverables include: Data architecture, data workflow logical models, physical source data models, data profiling reports and data audits, data definitions, data taxonomy, data metrics, meta-data, data lineage, data cleansing services. Functions of our data team is to development and design, data quality management, reference and master data management, data integration, data governance. OWI is a fast-paced and dynamic organization. Individuals will be handling multiple activities in a team as well as individual contributor environment. DUTIES, TASKS, AND RESPONSIBILITIES: Â·Activities: data modeling, data audit, detailed data design, define rules, establish master data solutions, define hierarchies, distribute reference and master data, profile, analyze, assess data quality, design data quality management procedures, clean and correct data quality defects, establish data governance. Â·Experienced utilizing HANA studio data modeler which should include initial setup, calculations and, calculation and analytical views, data base schemas, creating attribute user/role creation. Â·Setting up security, Analytic privileges, user integration services, SQL script, SLT, SDA, SDI and HANA Live solution models. Â·Demonstrate critical thinking, analytical skills, and employ judgment to offer thoughtful, concise input toward resolutions of problems. Â·Assist team building the BW4HANA modeler including standard and custom development and deployment of EWD design building BW objects e.g. Composite Providers, Advanced DSOâ€™s, ODS Views, Data Sources, Data Loading using SLT. Â·Be able to translate data requirements into business processes and reverse engineer business processes into data requirements Comprehension of DevOps and Agile development and application to data centric architecture and solutions Â·Leadership skills needed to successfully promote ideas, coordinate work activities, and plan deliverables within a project team. SKILLS, KNOWLEDGE, AND ABILITIES: Â·Advanced expert database handling languages (SQL and variants) Â·Expert in data modeling (physical and logical), ER diagrams, data dictionary, data map, normalize de-normalize, agile data modeling Â·Practical skill sets in BI and Data visualization tools Â·Knowledge of other programming languages and ability to write code (i.e. VBA, python, XML) Â·Working knowledge of ETL Â·Working knowledge of SAP Â·Basic Project Management and Business Process modeling Â·Minimum Bachelorâ€™s Degree in Engineering Technology, Computer Science, or closely related field. Â·A minimum of 3 yearsâ€™ experience in SAP Data Management and Governance, SAP Data Services (Data Extract, Data Profiling, de-duplication) Â·Advanced competency in SAP HANA, SQL Server Database, Tableau and Alteryx Â·Experience in transactional modeling and dimensional data warehouse model development with at least 4 years developing in HANA. Â·Work with other IM data modelers and ETL developers to design data loads into HANA Â·Excellent verbal and written communication skills with a strong focus on the ability to clearly articulate and discuss technical issues with both technical and business personnel. Â·Bachelor degree in Computer Science, Math or a related IT field or equivalent work experience in an IT field required Â·Strong analytical skills, able to effectively solve problems in a timely manner | E15: 3.1 | F15: Old World Industries 3.1 | G15: Northbrook, IL | H15: Northbrook, IL | I15: 201 to 500 employees | J15: 1973 | K15: Company - Private | L15: Chemical Manufacturing | M15: Manufacturing | N15: $1 to $2 billion (USD) | O15: -1
